Workbook
Name trak1: 'Assessments-Master'!$V$2:$AI$694

Sheet Assessments-Master
A1: Joining Year | B1: Track Number | C1: LAST Batch Year | D1: Category | E1: Batch Number | F1: WhatsApp Batch Name | G1: GURUVU GARU 1 | H1: GURUVU GARU 2 / TA | I1: GURUVU GARU 3 / TA | J1: Student Status | K1: LAST 4-WEEKS ATTENDANCE | L1: OVERALL AKSHARA / SWARA JNANAM | M1: OVERALL EXAM BACKLOG | N1: Roll Number | O1: Last Name | P1: First Name | Q1: Full Name | R1: Country Code | S1: Phone Number | T1: Time zone | U1: YOB | V1: Guru Vandana SHLOKAS | W1: YAGNOPAVEETA Dharanam, Avaposanam, panchangam | X1: Shraddha | Y1: Medha | Z1: Durga | AA1: Sri Suktam | AB1: Purusha | AC1: Ganapathi | AD1: Narayana | AE1: Sandhya Vandanam 1 | AF1: Sandhya Vandanam 2 | AG1: Sandhya Vandanam 3 | AH1: Brahma Yagnam | AI1: TRACK 1 CERTIFICATION EXAM STATUS | AJ1: Vishnu | AK1: Bhu Suktam | AL1: Neela | AM1: Bhagya | AN1: Brahma | AO1: Sarpa | AP1: Saraswathi | AQ1: Govu | AR1: Pavamana | AS1: Ayushya | AT1: Navagraha | AU1: Maha Mantra Pushpam | AV1: TRACK 2 CERTIFICATION EXAM STATUS | AW1: Deepa Prajvalanam | AX1: Trisuparnam | AY1: Manyu Suktam | AZ1: Vaishvanara Suktam | BA1: Rudram Namakam | BB1: Rudram Chamakam | BC1: Shakunadi | BD1: Ganapati Pooja | BE1: Punyaha vaachanam | BF1: TRACK 3 CERTIFICATION EXAM STATUS | BG1: Mahanyasam - 1 | BH1: Mahanyasam - 2 | BI1: Mahanyasam - 3 | BJ1: Mahanyasam - 4 | BK1: Dasashanti | BL1: Samrajya Pattabhishekam | BM1: TRACK 4 CERTIFICATION EXAM | BN1: Seeksha Valli | BO1: Ananda Valli | BP1: Brughu Valli | BQ1: Chitti 1 | BR1: Chitti 2 | BS1: Maha Narayanam 1 | BT1: Maha Narayanam 2 | BU1: Maha Narayanam 3 | BV1: TRACK 5 CERTIFICATION EXAM STATUS | BW1: Nakshatreshti 1 | BX1: Nakshatreshti 2 | BY1: Pancha katakamulu 1 Samjnanam 1 | BZ1: Pancha katakamulu 1 Samjnanam 2 | CA1: Pancha katakamulu 2 Lokosi 1 | CB1: Pancha katakamulu 2 Lokosi 2 | CC1: Pancha katakamulu 3 Thubyam 1 | CD1: Pancha katakamulu 3 Thubyam 2 | CE1: TRACK 6 CERTIFICATION EXAM STATUS | CF1: Pancha katakamulu 4 Arunam 1 | CG1: Pancha katakamulu 4 Arunam 2 | CH1: Pancha katakamulu 4 Arunam 3 | CI1: Pancha katakamulu 4 Arunam 4 | CJ1: Pancha katakamulu 5 Swadhyaya Brahmanam 1 | CK1: Pancha katakamulu 5 Swadhyaya Brahmanam 2 | CL1: Pancha katakamulu 5 Swadhyaya Brahmanam 3 | CM1: TRACK 7 CERTIFICATION EXAM STATUS | CN1: Veda Aseervachanam 1 | CO1: Veda Aseervachanam 2 | CP1: Purnakumbha Swagata Mantras | CQ1: Pancha anuvaaka Mantras | CR1: Anna Sooktam 1 | CS1: Anna Sooktam 2 | CT1: Prayojanaartha Mantraah 1 | CU1: Prayojanaartha Mantraah 2 | CV1: Shatpatra Prayogam | CW1: Jayadayah | CX1: Poornahuti &Agni Pradakshina | CY1: TRACK 8 CERTIFICATION EXAM STATUS
A2: {=_xludf.XLOOKUP(S2,Master_Registrations!P:P,Master_Registrations!A:A,"")} -> #NAME? | B2: VED-01 | C2: 2026 | D2: BR | E2: 1 | F2: =CONCATENATE(B2,"-",C2,"-",D2,"-",E2) -> VED-01-2026-BR-1 | G2: Niranjan Penumarthy | H2: Kiran Deshpande | J2: Active | N2: R1 | O2: Ayachitula | P2: Hrishikesh | Q2: =_xludf.TEXTJOIN(" ",TRUE,O2:P2) -> #NAME? | R2: +91 | S2: 9986458997 | T2: 1-INDIA IST | U2: 2010 | V2: 1 | W2: 1 | X2: 1 | Y2: 1 | Z2: 1 | AA2: -1 | AB2: -1 | AC2: -1 | AD2: -1 | AE2: -1 | AF2: -1 | AG2: -1 | AH2: -1 | AI2: -1
A3: {=_xludf.XLOOKUP(S3,Master_Registrations!P:P,Master_Registrations!A:A,"")} -> #NAME? | B3: VED-01 | C3: 2026 | D3: BR | E3: 1 | F3: =CONCATENATE(B3,"-",C3,"-",D3,"-",E3) -> VED-01-2026-BR-1 | G3: Niranjan Penumarthy | H3: Kiran Deshpande | J3: Active | N3: R2 | O3: Ayachitula | P3: Sriram Charan | Q3: =_xludf.TEXTJOIN(" ",TRUE,O3:P3) -> #NAME? | R3: +91 | S3: 9986458997 | T3: 1-INDIA IST | U3: 2012 | V3: 1 | W3: 1 | X3: 1 | Y3: 1 | Z3: 1 | AA3: -1 | AB3: -1 | AC3: -1 | AD3: -1 | AE3: -1 | AF3: -1 | AG3: -1 | AH3: -1 | AI3: -1
A4: {=_xludf.XLOOKUP(S4,Master_Registrations!P:P,Master_Registrations!A:A,"")} -> #NAME? | B4: VED-01 | C4: 2026 | D4: BR | E4: 1 | F4: =CONCATENATE(B4,"-",C4,"-",D4,"-",E4) -> VED-01-2026-BR-1 | G4: Niranjan Penumarthy | H4: Kiran Deshpande | J4: Active | N4: R3 | O4: Challa | P4: Achyuth Ram | Q4: =_xludf.TEXTJOIN(" ",TRUE,O4:P4) -> #NAME? | R4: +91 | S4: 9885600552 | T4: 1-INDIA IST | U4: 2018 | V4: 1 | W4: -1 | X4: 1 | Y4: 1 | Z4: 1 | AA4: -1 | AB4: -1 | AC4: -1 | AD4: -1 | AE4: 1 | AF4: 1 | AG4: 1 | AH4: -1 | AI4: -1
A5: {=_xludf.XLOOKUP(S5,Master_Registrations!P:P,Master_Registrations!A:A,"")} -> #NAME? | B5: VED-01 | C5: 2026 | D5: BR | E5: 1 | F5: =CONCATENATE(B5,"-",C5,"-",D5,"-",E5) -> VED-01-2026-BR-1 | G5: Niranjan Penumarthy | H5: Kiran Deshpande | J5: Active | N5: R4 | O5: Dokka | P5: Jagannadh | Q5: =_xludf.TEXTJOIN(" ",TRUE,O5:P5) -> #NAME? | R5: +1 | S5: 7147913258 | T5: 3-USA CST | U5: 2011 | V5: -1 | W5: -1 | X5: -1 | Y5: -1 | Z5: -1 | AA5: -1 | AB5: -1 | AC5: -1 | AD5: -1 | AE5: -1 | AF5: -1 | AG5: -1 | AH5: -1 | AI5: -1
A6: {=_xludf.XLOOKUP(S6,Master_Registrations!P:P,Master_Registrations!A:A,"")} -> #NAME? | B6: VED-01 | C6: 2026 | D6: BR | E6: 1 | F6: =CONCATENATE(B6,"-",C6,"-",D6,"-",E6) -> VED-01-2026-BR-1 | G6: Niranjan Penumarthy | H6: Kiran Deshpande | J6: Active | N6: R5 | O6: Gorthy | P6: Anand krishna | Q6: =_xludf.TEXTJOIN(" ",TRUE,O6:P6) -> #NAME? | R6: +1 | S6: 8148826399 | T6: 3-USA CST | U6: 2016 | V6: -1 | W6: -1 | X6: 1 | Y6: -1 | Z6: -1 | AA6: -1 | AB6: -1 | AC6: -1 | AD6: -1 | AE6: -1 | AF6: -1 | AG6: -1 | AH6: -1 | AI6: -1
A7: {=_xludf.XLOOKUP(S7,Master_Registrations!P:P,Master_Registrations!A:A,"")} -> #NAME? | B7: VED-01 | C7: 2026 | D7: BR | E7: 1 | F7: =CONCATENATE(B7,"-",C7,"-",D7,"-",E7) -> VED-01-2026-BR-1 | G7: Niranjan Penumarthy | H7: Kiran Deshpande | J7: Active | N7: R6 | O7: Jandhyala | P7: Venkata Karthikeya Aashrith | Q7: =_xludf.TEXTJOIN(" ",TRUE,O7:P7) -> #NAME? | R7: +91 | S7: 9840573053 | T7: 1-INDIA IST | U7: 2016 | V7: -1 | W7: -1 | X7: 1 | Y7: -1 | Z7: -1 | AA7: -1 | AB7: -1 | AC7: -1 | AD7: -1 | AE7: -1 | AF7: -1 | AG7: -1 | AH7: -1 | AI7: -1
A8: {=_xludf.XLOOKUP(S8,Master_Registrations!P:P,Master_Registrations!A:A,"")} -> #NAME? | B8: VED-01 | C8: 2026 | D8: BR | E8: 1 | F8: =CONCATENATE(B8,"-",C8,"-",D8,"-",E8) -> VED-01-2026-BR-1 | G8: Niranjan Penumarthy | H8: Kiran Deshpande | J8: Active | N8: R7 | O8: Kavuri | P8: Sriram | Q8: =_xludf.TEXTJOIN(" ",TRUE,O8:P8) -> #NAME? | R8: +91 | S8: 9441975657 | T8: 1-INDIA IST | U8: 2013 | V8: 1 | W8: 1 | X8: 1 | Y8: 1 | Z8: 1 | AA8: -1 | AB8: -1 | AC8: -1 | AD8: -1 | AE8: 2 | AF8: 2 | AG8: 2 | AH8: -1 | AI8: -1
A9: {=_xludf.XLOOKUP(S9,Master_Registrations!P:P,Master_Registrations!A:A,"")} -> #NAME? | B9: VED-01 | C9: 2026 | D9: BR | E9: 1 | F9: =CONCATENATE(B9,"-",C9,"-",D9,"-",E9) -> VED-01-2026-BR-1 | G9: Niranjan Penumarthy | H9: Kiran Deshpande | J9: Active | N9: R8 | O9: Kidambi | P9: Vedkrishna | Q9: =_xludf.TEXTJOIN(" ",TRUE,O9:P9) -> #NAME? | R9: +91 | S9: 9441346181 | T9: 1-INDIA IST | U9: 2012 | V9: 1 | W9: -1 | X9: 1 | Y9: -1 | Z9: -1 | AA9: -1 | AB9: -1 | AC9: -1 | AD9: -1 | AE9: -1 | AF9: -1 | AG9: -1 | AH9: -1 | AI9: -1
A10: {=_xludf.XLOOKUP(S10,Master_Registrations!P:P,Master_Registrations!A:A,"")} -> #NAME? | B10: VED-01 | C10: 2026 | D10: BR | E10: 1 | F10: =CONCATENATE(B10,"-",C10,"-",D10,"-",E10) -> VED-01-2026-BR-1 | G10: Niranjan Penumarthy | H10: Kiran Deshpande | J10: Active | N10: R9 | O10: Mandapaka | P10: Krishna Sai Sudeep Sarma | Q10: =_xludf.TEXTJOIN(" ",TRUE,O10:P10) -> #NAME? | R10: +91 | S10: 9052550010 | T10: 1-INDIA IST | U10: 2014 | V10: 1 | W10: -1 | X10: 1 | Y10: 1 | Z10: 1 | AA10: -1 | AB10: -1 | AC10: -1 | AD10: -1 | AE10: 1 | AF10: 1 | AG10: 1 | AH10: -1 | AI10: -1
A11: {=_xludf.XLOOKUP(S11,Master_Registrations!P:P,Master_Registrations!A:A,"")} -> #NAME? | B11: VED-01 | C11: 2026 | D11: BR | E11: 1 | F11: =CONCATENATE(B11,"-",C11,"-",D11,"-",E11) -> VED-01-2026-BR-1 | G11: Niranjan Penumarthy | H11: Kiran Deshpande | J11: Active | N11: R10 | O11: Mannava | P11: Atharv | Q11: =_xludf.TEXTJOIN(" ",TRUE,O11:P11) -> #NAME? | R11: +1 | S11: 3182434371 | T11: 3-USA CST | U11: 2010 | V11: -1 | W11: -1 | X11: -1 | Y11: -1 | Z11: -1 | AA11: -1 | AB11: -1 | AC11: -1 | AD11: -1 | AE11: -1 | AF11: -1 | AG11: -1 | AH11: -1 | AI11: -1
A12: {=_xludf.XLOOKUP(S12,Master_Registrations!P:P,Master_Registrations!A:A,"")} -> #NAME? | B12: VED-01 | C12: 2026 | D12: BR | E12: 1 | F12: =CONCATENATE(B12,"-",C12,"-",D12,"-",E12) -> VED-01-2026-BR-1 | G12: Niranjan Penumarthy | H12: Kiran Deshpande | J12: Active | N12: R11 | O12: Mannava | P12: Vahin | Q12: =_xludf.TEXTJOIN(" ",TRUE,O12:P12) -> #NAME? | R12: +1 | S12: 3182434371 | T12: 3-USA CST | U12: 2014 | V12: -1 | W12: -1 | X12: -1 | Y12: -1 | Z12: -1 | AA12: -1 | AB12: -1 | AC12: -1 | AD12: -1 | AE12: -1 | AF12: -1 | AG12: -1 | AH12: -1 | AI12: -1
A13: {=_xludf.XLOOKUP(S13,Master_Registrations!P:P,Master_Registrations!A:A,"")} -> #NAME? | B13: VED-01 | C13: 2026 | D13: BR | E13: 1 | F13: =CONCATENATE(B13,"-",C13,"-",D13,"-",E13) -> VED-01-2026-BR-1 | G13: Niranjan Penumarthy | H13: Kiran Deshpande | J13: Active | N13: R12 | O13: Remella | P13: Srikar Sreshta | Q13: =_xludf.TEXTJOIN(" ",TRUE,O13:P13) -> #NAME? | R13: +91 | S13: 9160750001 | T13: 1-INDIA IST | U13: 2012 | V13: 1 | W13: 1 | X13: 1 | Y13: 1 | Z13: 1 | AA13: -1 | AB13: -1 | AC13: -1 | AD13: -1 | AE13: 1 | AF13: 1 | AG13: 1 | AH13: -1 | AI13: -1
... A15: {=_xludf.XLOOKUP(S15,Master_Registrations!P:P,Master_Registrations!A:A,"")} -> #NAME? | B15: VED-01 | C15: 2026 | D15: BR | E15: 1 | F15: =CONCATENATE(B15,"-",C15,"-",D15,"-",E15) -> VED-01-2026-BR-1 | G15: Niranjan Penumarthy | H15: Kiran Deshpande | J15: Active | N15: R14 | O15: Vemuri | P15: Anand Karthikeya | Q15: =_xludf.TEXTJOIN(" ",TRUE,O15:P15) -> #NAME? | R15: +91 | S15: 9930904698 | T15: 1-INDIA IST | U15: 2016 | V15: 1 | W15: -1 | X15: 1 | Y15: 1 | Z15: 1 | AA15: -1 | AB15: -1 | AC15: -1 | AD15: -1 | AE15: 2 | AF15: 2 | AG15: 2 | AH15: 1 | AI15: -1
A16: {=_xludf.XLOOKUP(S16,Master_Registrations!P:P,Master_Registrations!A:A,"")} -> #NAME? | B16: VED-01 | C16: 2026 | D16: BR | E16: 2 | F16: =CONCATENATE(B16,"-",C16,"-",D16,"-",E16) -> VED-01-2026-BR-2 | G16: Damodaram Tekuru | H16: Mavuduru Uma Maheshwar | J16: Active | K16: 1 | N16: R1 | O16: Akella | P16: Sai Surya Manikya Srikar Sharma | Q16: =_xludf.TEXTJOIN(" ",TRUE,O16:P16) -> #NAME? | R16: +91 | S16: 8985827908 | T16: 1-INDIA IST | U16: 2014 | V16: 1 | W16: -1 | X16: 1 | Y16: 1 | Z16: 1 | AA16: -1 | AB16: -1
A17: {=_xludf.XLOOKUP(S17,Master_Registrations!P:P,Master_Registrations!A:A,"")} -> #NAME? | B17: VED-01 | C17: 2026 | D17: BR | E17: 2 | F17: =CONCATENATE(B17,"-",C17,"-",D17,"-",E17) -> VED-01-2026-BR-2 | G17: Damodaram Tekuru | H17: Mavuduru Uma Maheshwar | J17: Active | K17: 1 | N17: R2 | O17: Ambatipudi | P17: Vibhu Sankar | Q17: =_xludf.TEXTJOIN(" ",TRUE,O17:P17) -> #NAME? | R17: +91 | S17: 7893641027 | T17: 1-INDIA IST | U17: 2016 | V17: 1 | W17: -1 | X17: -1 | Y17: 1 | Z17: 1 | AA17: -1 | AB17: -1
A18: {=_xludf.XLOOKUP(S18,Master_Registrations!P:P,Master_Registrations!A:A,"")} -> #NAME? | B18: VED-01 | C18: 2026 | D18: BR | E18: 2 | F18: =CONCATENATE(B18,"-",C18,"-",D18,"-",E18) -> VED-01-2026-BR-2 | G18: Damodaram Tekuru | H18: Mavuduru Uma Maheshwar | J18: Active | K18: 1 | N18: R3 | O18: Gorthi | P18: Shanmukha Sri Datta | Q18: =_xludf.TEXTJOIN(" ",TRUE,O18:P18) -> #NAME? | R18: +91 | S18: 9611932143 | T18: 1-INDIA IST | U18: 2012 | V18: 1 | W18: -1 | X18: -1 | Y18: 1 | Z18: -1 | AA18: -1 | AB18: -1
A19: {=_xludf.XLOOKUP(S19,Master_Registrations!P:P,Master_Registrations!A:A,"")} -> #NAME? | B19: VED-01 | C19: 2026 | D19: BR | E19: 2 | F19: =CONCATENATE(B19,"-",C19,"-",D19,"-",E19) -> VED-01-2026-BR-2 | G19: Damodaram Tekuru | H19: Mavuduru Uma Maheshwar | J19: Active | K19: 1 | N19: R4 | O19: Keely | P19: Akshay Rao | Q19: =_xludf.TEXTJOIN(" ",TRUE,O19:P19) -> #NAME? | R19: +91 | S19: 9740274684 | T19: 1-INDIA IST | U19: 2011 | V19: 1 | W19: -1 | X19: -1 | Y19: 1 | Z19: 1 | AA19: -1 | AB19: 1
A20: {=_xludf.XLOOKUP(S20,Master_Registrations!P:P,Master_Registrations!A:A,"")} -> #NAME? | B20: VED-01 | C20: 2026 | D20: BR | E20: 2 | F20: =CONCATENATE(B20,"-",C20,"-",D20,"-",E20) -> VED-01-2026-BR-2 | G20: Damodaram Tekuru | H20: Mavuduru Uma Maheshwar | J20: Active | K20: 1 | N20: R5 | O20: Kota | P20: Yasasvi Pranav | Q20: =_xludf.TEXTJOIN(" ",TRUE,O20:P20) -> #NAME? | R20: +91 | S20: 9494398425 | T20: 1-INDIA IST | U20: 2012 | V20: -1 | W20: -1 | X20: 1 | Y20: -1 | Z20: -1 | AA20: -1 | AB20: -1
A21: {=_xludf.XLOOKUP(S21,Master_Registrations!P:P,Master_Registrations!A:A,"")} -> #NAME? | B21: VED-01 | C21: 2026 | D21: BR | E21: 2 | F21: =CONCATENATE(B21,"-",C21,"-",D21,"-",E21) -> VED-01-2026-BR-2 | G21: Damodaram Tekuru | H21: Mavuduru Uma Maheshwar | J21: Active | K21: 1 | N21: R6 | O21: Kuppa | P21: Saketh Ram | Q21: =_xludf.TEXTJOIN(" ",TRUE,O21:P21) -> #NAME? | R21: +91 | S21: 6305438951 | T21: 1-INDIA IST | U21: 2014 | V21: 1 | W21: -1 | X21: -1 | Y21: -1 | Z21: -1 | AA21: -1 | AB21: -1
A22: {=_xludf.XLOOKUP(S22,Master_Registrations!P:P,Master_Registrations!A:A,"")} -> #NAME? | B22: VED-01 | C22: 2026 | D22: BR | E22: 2 | F22: =CONCATENATE(B22,"-",C22,"-",D22,"-",E22) -> VED-01-2026-BR-2 | G22: Damodaram Tekuru | H22: Mavuduru Uma Maheshwar | J22: Active | N22: R8 | O22: Mylavarapu | P22: Advaith | Q22: Mylavarapu Advaith | R22: +1 | S22: 5135601785 | T22: 2-USA EST | U22: 2016 | V22: -1 | W22: -1 | X22: -1 | Y22: -1 | Z22: -1 | AA22: -1 | AB22: -1
A23: {=_xludf.XLOOKUP(S23,Master_Registrations!P:P,Master_Registrations!A:A,"")} -> #NAME? | B23: VED-01 | C23: 2026 | D23: BR | E23: 2 | F23: =CONCATENATE(B23,"-",C23,"-",D23,"-",E23) -> VED-01-2026-BR-2 | G23: Damodaram Tekuru | H23: Mavuduru Uma Maheshwar | J23: Active | N23: R9 | O23: Niraghatam | P23: Surya | Q23: Niraghatam Surya | R23: +1 | S23: 4805932217 | T23: 3-USA CST | U23: 2014 | V23: -1 | W23: -1 | X23: -1 | Y23: -1 | Z23: -1 | AA23: -1 | AB23: -1
A24: {=_xludf.XLOOKUP(S24,Master_Registrations!P:P,Master_Registrations!A:A,"")} -> #NAME? | B24: VED-01 | C24: 2026 | D24: BR | E24: 2 | F24: =CONCATENATE(B24,"-",C24,"-",D24,"-",E24) -> VED-01-2026-BR-2 | G24: Damodaram Tekuru | H24: Mavuduru Uma Maheshwar | J24: Active | N24: R10 | O24: Puranam | P24: Shanmukhaditya | Q24: =_xludf.TEXTJOIN(" ",TRUE,O24:P24) -> #NAME? | R24: +91 | S24: 9848847831 | T24: 1-INDIA IST | U24: 2013 | V24: -1 | W24: -1 | X24: -1 | Y24: -1 | Z24: -1 | AA24: -1 | AB24: -1
A25: {=_xludf.XLOOKUP(S25,Master_Registrations!P:P,Master_Registrations!A:A,"")} -> #NAME? | B25: VED-01 | C25: 2026 | D25: BR | E25: 2 | F25: =CONCATENATE(B25,"-",C25,"-",D25,"-",E25) -> VED-01-2026-BR-2 | G25: Damodaram Tekuru | H25: Mavuduru Uma Maheshwar | J25: Active | K25: 1 | N25: R11 | O25: Saripalli | P25: Subhrahmanya Aditya | Q25: =_xludf.TEXTJOIN(" ",TRUE,O25:P25) -> #NAME? | R25: +91 | S25: 9886333667 | T25: 1-INDIA IST | U25: 2017 | V25: 1 | W25: -1 | X25: 1 | Y25: 1 | Z25: -1 | AA25: -1 | AB25: -1
A26: {=_xludf.XLOOKUP(S26,Master_Registrations!P:P,Master_Registrations!A:A,"")} -> #NAME? | B26: VED-01 | C26: 2026 | D26: BR | E26: 2 | F26: =CONCATENATE(B26,"-",C26,"-",D26,"-",E26) -> VED-01-2026-BR-2 | G26: Damodaram Tekuru | H26: Mavuduru Uma Maheshwar | J26: Active | K26: 1 | N26: R12 | O26: Tenjerla | P26: Sri Dhruva Mahesh | Q26: =_xludf.TEXTJOIN(" ",TRUE,O26:P26) -> #NAME? | R26: +91 | S26: 8147232263 | T26: 1-INDIA IST | U26: 2012 | V26: 1 | W26: -1 | X26: -1 | Y26: 1 | Z26: 1 | AA26: -1 | AB26: -1
A27: {=_xludf.XLOOKUP(S27,Master_Registrations!P:P,Master_Registrations!A:A,"")} -> #NAME? | B27: VED-01 | C27: 2026 | D27: BR | E27: 2 | F27: =CONCATENATE(B27,"-",C27,"-",D27,"-",E27) -> VED-01-2026-BR-2 | G27: Damodaram Tekuru | H27: Mavuduru Uma Maheshwar | J27: Active | N27: R13 | O27: Tenjerla | P27: Ganesh Karthik | Q27: Tenjerla Ganesh Karthik | R27: +91 | S27: 8147232263 | T27: 1-INDIA IST | U27: 2010 | V27: -1 | W27: -1 | X27: -1 | Y27: -1 | Z27: -1 | AA27: -1 | AB27: -1
A28: {=_xludf.XLOOKUP(S28,Master_Registrations!P:P,Master_Registrations!A:A,"")} -> #NAME? | B28: VED-01 | C28: 2026 | D28: BR | E28: 2 | F28: =CONCATENATE(B28,"-",C28,"-",D28,"-",E28) -> VED-01-2026-BR-2 | G28: Damodaram Tekuru | H28: Mavuduru Uma Maheshwar | J28: Active | N28: R14 | O28: Varanasi | P28: Savarni | Q28: =_xludf.TEXTJOIN(" ",TRUE,O28:P28) -> #NAME? | R28: +91 | S28: 9866707774 | T28: 1-INDIA IST | U28: 2013 | V28: -1 | W28: -1 | X28: -1 | Y28: -1 | Z28: -1 | AA28: -1 | AB28: -1
A29: {=_xludf.XLOOKUP(S29,Master_Registrations!P:P,Master_Registrations!A:A,"")} -> #NAME? | B29: VED-01 | C29: 2026 | D29: BR | E29: 2 | F29: =CONCATENATE(B29,"-",C29,"-",D29,"-",E29) -> VED-01-2026-BR-2 | G29: Damodaram Tekuru | H29: Mavuduru Uma Maheshwar | J29: Active | N29: R15 | O29: Vedula | P29: Jithamithra | Q29: =_xludf.TEXTJOIN(" ",TRUE,O29:P29) -> #NAME? | R29: +1 | S29: 2488021056 | T29: 2-USA EST | U29: 2016 | V29: 1 | W29: -1 | X29: 1 | Y29: 1 | Z29: 1 | AA29: -1 | AB29: -1
A30: {=_xludf.XLOOKUP(S30,Master_Registrations!P:P,Master_Registrations!A:A,"")} -> #NAME? | B30: VED-01 | C30: 2026 | D30: BR | E30: 3 | F30: =CONCATENATE(B30,"-",C30,"-",D30,"-",E30) -> VED-01-2026-BR-3 | G30: Sripada Srinivas | H30: Shivakumar Challa | J30: Active | K30: 1 | N30: R1 | O30: Ayyalasomayajula | P30: Soorya Manoo | Q30: =_xludf.TEXTJOIN(" ",TRUE,O30:P30) -> #NAME? | R30: +1 | S30: 8327481679 | T30: 3-USA CST | U30: 2015 | V30: -1 | W30: -1 | X30: -1
A31: {=_xludf.XLOOKUP(S31,Master_Registrations!P:P,Master_Registrations!A:A,"")} -> #NAME? | B31: VED-01 | C31: 2026 | D31: BR | E31: 3 | F31: =CONCATENATE(B31,"-",C31,"-",D31,"-",E31) -> VED-01-2026-BR-3 | G31: Sripada Srinivas | H31: Shivakumar Challa | J31: Active | K31: 1 | N31: R2 | O31: Bhattar | P31: Vaishnav | Q31: =_xludf.TEXTJOIN(" ",TRUE,O31:P31) -> #NAME? | R31: +1 | S31: 8382620227 | T31: 2-USA EST | U31: 2010 | V31: -1 | W31: -1 | X31: -1
A32: {=_xludf.XLOOKUP(S32,Master_Registrations!P:P,Master_Registrations!A:A,"")} -> #NAME? | B32: VED-01 | C32: 2026 | D32: BR | E32: 3 | F32: =CONCATENATE(B32,"-",C32,"-",D32,"-",E32) -> VED-01-2026-BR-3 | G32: Sripada Srinivas | H32: Shivakumar Challa | J32: Active | K32: 1 | N32: R3 | O32: Burugula | P32: Abhiram | Q32: =_xludf.TEXTJOIN(" ",TRUE,O32:P32) -> #NAME? | R32: +1 | S32: 6099370666 | T32: 3-USA CST | U32: 2018 | V32: -1 | W32: -1 | X32: -1
A33: {=_xludf.XLOOKUP(S33,Master_Registrations!P:P,Master_Registrations!A:A,"")} -> #NAME? | B33: VED-01 | C33: 2026 | D33: BR | E33: 3 | F33: =CONCATENATE(B33,"-",C33,"-",D33,"-",E33) -> VED-01-2026-BR-3 | G33: Sripada Srinivas | H33: Shivakumar Challa | J33: Active | K33: 1 | N33: R4 | O33: Julakanti | P33: Venkata Vishruth Vachan | Q33: =_xludf.TEXTJOIN(" ",TRUE,O33:P33) -> #NAME? | R33: +1 | S33: 5129034955 | T33: 3-USA CST | U33: 2011 | V33: -1 | W33: -1 | X33: -1
A34: {=_xludf.XLOOKUP(S34,Master_Registrations!P:P,Master_Registrations!A:A,"")} -> #NAME? | B34: VED-01 | C34: 2026 | D34: BR | E34: 3 | F34: =CONCATENATE(B34,"-",C34,"-",D34,"-",E34) -> VED-01-2026-BR-3 | G34: Sripada Srinivas | H34: Shivakumar Challa | J34: Active | N34: R5 | O34: Kandukuri | P34: Veda Rushi | Q34: =_xludf.TEXTJOIN(" ",TRUE,O34:P34) -> #NAME? | R34: +91 | S34: 8688328602 | T34: 1-INDIA IST | U34: 2013 | V34: -1 | W34: -1 | X34: -1
A35: {=_xludf.XLOOKUP(S35,Master_Registrations!P:P,Master_Registrations!A:A,"")} -> #NAME? | B35: VED-01 | C35: 2026 | D35: BR | E35: 3 | F35: =CONCATENATE(B35,"-",C35,"-",D35,"-",E35) -> VED-01-2026-BR-3 | G35: Sripada Srinivas | H35: Shivakumar Challa | J35: Active | K35: 1 | N35: R6 | O35: Kota | P35: Karthikeya | Q35: =_xludf.TEXTJOIN(" ",TRUE,O35:P35) -> #NAME? | R35: +91 | S35: 8106966654 | T35: 1-INDIA IST | U35: 2014 | V35: -1 | W35: -1 | X35: -1
A36: =_xlfn.XLOOKUP(S36,Master_Registrations!P:P,Master_Registrations!A:A,"") -> 2025 | B36: VED-01 | C36: 2026 | D36: BR | E36: 3 | F36: =CONCATENATE(B36,"-",C36,"-",D36,"-",E36) -> VED-01-2026-BR-3 | G36: Sripada Srinivas | H36: Shivakumar Challa | J36: Active | N36: R7 | O36: Mellachervu | P36: Srikar | Q36: =_xludf.TEXTJOIN(" ",TRUE,O36:P36) -> #NAME? | R36: +1 | S36: 8609048328 | T36: 3-USA CST | U36: 2013 | V36: -1 | W36: -1 | X36: -1
A37: {=_xludf.XLOOKUP(S37,Master_Registrations!P:P,Master_Registrations!A:A,"")} -> #NAME? | B37: VED-01 | C37: 2026 | D37: BR | E37: 3 | F37: =CONCATENATE(B37,"-",C37,"-",D37,"-",E37) -> VED-01-2026-BR-3 | G37: Sripada Srinivas | H37: Shivakumar Challa | J37: Active | K37: 1 | N37: R8 | O37: Murthinty | P37: Venkata Shivark | Q37: =_xludf.TEXTJOIN(" ",TRUE,O37:P37) -> #NAME? | R37: +1 | S37: 3068804239 | T37: 2-USA EST | U37: 2013 | V37: -1 | W37: -1 | X37: -1
A38: {=_xludf.XLOOKUP(S38,Master_Registrations!P:P,Master_Registrations!A:A,"")} -> #NAME? | B38: VED-01 | C38: 2026 | D38: BR | E38: 3 | F38: =CONCATENATE(B38,"-",C38,"-",D38,"-",E38) -> VED-01-2026-BR-3 | G38: Sripada Srinivas | H38: Shivakumar Challa | J38: Active | K38: 1 | N38: R9 | O38: Patiballa | P38: Krishna Vamsee | Q38: =_xludf.TEXTJOIN(" ",TRUE,O38:P38) -> #NAME? | R38: +91 | S38: 8341673687 | T38: 1-INDIA IST | U38: 2011 | V38: -1 | W38: -1 | X38: -1
A39: {=_xludf.XLOOKUP(S39,Master_Registrations!P:P,Master_Registrations!A:A,"")} -> #NAME? | B39: VED-01 | C39: 2026 | D39: BR | E39: 3 | F39: =CONCATENATE(B39,"-",C39,"-",D39,"-",E39) -> VED-01-2026-BR-3 | G39: Sripada Srinivas | H39: Shivakumar Challa | J39: Active | K39: 1 | N39: R10 | O39: Potukuchi | P39: Sivateja | Q39: =_xludf.TEXTJOIN(" ",TRUE,O39:P39) -> #NAME? | R39: +1 | S39: 8036293505 | T39: 4-USA MST/PST | U39: 2014 | V39: -1 | W39: -1 | X39: -1
A40: {=_xludf.XLOOKUP(S40,Master_Registrations!P:P,Master_Registrations!A:A,"")} -> #NAME? | B40: VED-01 | C40: 2026 | D40: BR | E40: 4 | F40: =CONCATENATE(B40,"-",C40,"-",D40,"-",E40) -> VED-01-2026-BR-4 | G40: Penumarthi Niranjana | H40: Gundu Rama Murthy | J40: Active | K40: 1 | N40: R1 | O40: Kandukuri | P40: Poorna Sashi | Q40: =_xludf.TEXTJOIN(" ",TRUE,O40:P40) -> #NAME? | R40: +91 | S40: 8688328602 | T40: 1-INDIA IST | U40: 2017 | V40: -1 | W40: -1 | X40: -1
A41: {=_xludf.XLOOKUP(S41,Master_Registrations!P:P,Master_Registrations!A:A,"")} -> #NAME? | B41: VED-01 | C41: 2026 | D41: BR | E41: 4 | F41: =CONCATENATE(B41,"-",C41,"-",D41,"-",E41) -> VED-01-2026-BR-4 | G41: Penumarthi Niranjana | H41: Gundu Rama Murthy | J41: Active | K41: 1 | N41: R2 | O41: Mandagondi | P41: Ravi Krishna Sathwik | Q41: =_xludf.TEXTJOIN(" ",TRUE,O41:P41) -> #NAME? | R41: +91 | S41: 9248585989 | T41: 1-INDIA IST | U41: 2012 | V41: -1 | W41: -1 | X41: -1
...

Sheet Master_Registrations
A1: REGISTERED | B1: Timestamp | C1: QUALIFIED? | D1: EMAIL SENT? | E1: WHATSAPP SENT? | F1: JOINED COMM GROUP? | G1: CATEGORY | H1: EMAIL ADDRESS | I1: LAST NAME | J1: FIRST NAME | K1: FULL NAME | L1: YEAR OF BIRTH | M1: UPANAYANAM | N1: COUNTRY TIME ZONE | O1: COUNTRY CODE | P1: WHATSAPP | Q1: PRIMARY KEY | R1: CITY | S1: REFERENCE NAME | T1: REFERENCE PHONE | U1: GRUHASTA | V1: BRAHMACHARI | W1: VEDA SHAKA | X1: SPOKEN | Y1: READ | Z1: PARENT NAMES | AA1: JOB | AB1: PARENT STUDYING | AC1: GOAL | AD1: PROFICIENCY | AE1: PRIORITY | AF1: DRESS CODE | AG1: NO MEAT | AH1: NO ALCHOHOL | AI1: NO SMOKING | AJ1: COMMENTS
A2: 2024 | B2: 45372.928 | C2: 3-ARCHAKA? | D2: NO | E2: NO | F2: NO | G2: 1-ADULT OVER 16 YRS | H2: harish19wipro@gmail.com | I2: Cherukuru | J2: Harish Kumar | K2: =_xludf.TEXTJOIN(" ",TRUE,I2:J2) -> #NAME? | L2: 1985 | N2: 1-INDIA IST | O2: +91 | P2: 6303372946 | Q2: =P2&"/"&L2 -> 6303372946/1985 | R2: Hyderabad | S2: Muralidhar | T2: Muralidhar | U2: Kashyapasa, Vishwamitra, N/A | V2: Kashyapasa, Vishwamitra, N/A | W2: Rig Veda | X2: English, Telugu and Kannada | Y2: English, Telugu, Kannada and Hindi | Z2: N/A | AA2: 3-ARCHAKA? | AB2: Not Applicable (Not Registering a Child under 13) | AC2: Archakathvam and have to learn perfectly | AD2: Low - Did not learn from Traditional Guru, but learnt from books/audio and perform daily Sandhya Vandanam and other poojas through books | AE2: Yes, This is High Priority for me | AF2: Yes | AG2: Yes | AH2: Yes | AI2: Yes | AJ2: I would like to learn all sukthas, rudram etc perfectly
A3: 2024 | B3: 45384.322 | C3: 3-ARCHAKA? | D3: NO | E3: NO | F3: NO | G3: 1-ADULT OVER 16 YRS | H3: mphanishwaraprasad@gmail.com | I3: Maddhali | J3: Phanishwara Prasad | K3: =_xludf.TEXTJOIN(" ",TRUE,I3:J3) -> #NAME? | L3: 1988 | N3: 1-INDIA IST | O3: +91 | P3: 9963023525 | Q3: =P3&"/"&L3&"/"&K3 -> #NAME? | R3: WARANGAL | S3: M PHANISHWAR PRASAD | T3: M PHANISHWAR PRASAD | U3: KOUNDINYASA, BHARADWAJASA, N/A | V3: KOUNDINYASA, BHARADWAJASA, N/A | W3: YAJUR VEDA | X3: TELUGU | Y3: TELUGU | Z3: N/A | AA3: 3-ARCHAKA? | AB3: Not Applicable (Not Registering a Child under 13) | AC3: SMATHA | AD3: High - Learnt from Traditional Guru in perfect swaram/uccharana - perform nithya Sandhya Vandanam and can recite few Suktams in su-swaram | AE3: Yes, This is High Priority for me | AF3: Yes | AG3: Yes | AH3: Yes | AI3: Yes
A4: 2025 | B4: 45711.181 | C4: 3-ARCHAKA? | D4: NO | E4: NO | F4: NO | G4: 1-ADULT OVER 16 YRS | H4: vishu.9194@gmail.com | I4: Bethanabatla | J4: Kasi Vishwanath | K4: =_xludf.TEXTJOIN(" ",TRUE,I4:J4) -> #NAME? | L4: 1981 | N4: 1-INDIA IST | O4: +91 | P4: 9182062337 | Q4: =P4&"/"&L4&"/"&K4 -> #NAME? | R4: Hyderabad ,Telangana, India | S4: Gudipati pavan kumar | T4: Gudipati pavan kumar | U4: Bhardwaj, Kaasyapasa, Kaasyapasa | V4: Bhardwaj, Kaasyapasa, Kaasyapasa | W4: Yajur vedam | X4: Telugu | Y4: Telugu | Z4: No | AA4: 3-ARCHAKA? | AB4: Not Applicable (Not Registering a Child under 13) | AC4: I am in purohitam | AD4: High - Learnt from Traditional Guru in perfect swaram/uccharana - perform nithya Sandhya Vandanam and can recite few Suktams in su-swaram | AE4: Yes, This is High Priority for me | AF4: Yes | AG4: Yes | AH4: Yes | AI4: Yes
A5: 2025 | B5: 45856.15 | C5: 3-ARCHAKA? | D5: YES | E5: YES | F5: NO | G5: 1-ADULT OVER 16 YRS | H5: praneeth5599@gmail.com | I5: Vanamali | J5: Praneeth | K5: =_xludf.TEXTJOIN(" ",TRUE,I5:J5) -> #NAME? | L5: 1993 | M5: 2016 | N5: 1-INDIA IST | O5: +91 | P5: 9515248299 | Q5: =P5&"/"&L5&"/"&K5 -> #NAME? | R5: Hyderabad | S5: Mavuduru Umamaheswara rao berhampur | T5: Mavuduru Umamaheswara rao berhampur | U5: Bharadwajasa, Kasyapasa, Kasyapasa | V5: Bharadwajasa, Kasyapasa, Kasyapasa | W5: Rig veda | X5: Telugu english | Y5: Telugu english hindi | Z5: N/A | AA5: Tax Practitioner / Archaka Background | AB5: Not Applicable (Not Registering a Child under 13) | AC5: We have pourohithyam at my village. My dad is a purohith and Srividhya Poorna Dheeksha Parulu | AD5: High - Learnt from Traditional Guru in perfect swaram/uccharana - perform nithya Sandhya Vandanam and can recite few Suktams in su-swaram | AE5: Yes, This is High Priority for me | AF5: Yes | AG5: Yes | AH5: Yes | AI5: Yes | AJ5: I m glad if I able to learn from you.
A6: 2025 | B6: 45869.967 | C6: 3-ARCHAKA? | D6: NO | E6: NO | F6: NO | G6: 1-ADULT OVER 16 YRS | H6: vennampallysharma@gmail.com | I6: Vennampally | J6: Prashanth Sharma | K6: =_xludf.TEXTJOIN(" ",TRUE,I6:J6) -> #NAME? | L6: 1992 | M6: 2005 | N6: 1-INDIA IST | O6: +91 | P6: 8522870346 | Q6: =P6&"/"&L6&"/"&K6 -> #NAME? | R6: Narsampet | S6: B Chandresekar 9849639880 | T6: B Chandresekar 9849639881 | U6: Koundinyasa, Sri vatsasa, N/A | V6: Koundinyasa, Sri vatsasa, N/A | W6: Yajur Veda | X6: Telugu, Hindi, English | Y6: Telugu, Hindi, English | Z6: N/A | AA6: 3-ARCHAKA? | AB6: Not Applicable (Not Registering a Child under 13) | AC6: To upgrade my skills | AD6: Low - Did not learn from Traditional Guru, but learnt from books/audio and perform daily Sandhya Vandanam and other poojas through books | AE6: Yes, This is High Priority for me | AF6: Yes | AG6: Yes | AH6: Yes | AI6: Yes | AJ6: N/A
A7: 2025 | B7: 45912.193 | C7: 3-ARCHAKA? | D7: YES | E7: YES | F7: YES | G7: 1-ADULT OVER 16 YRS | H7: prathaparudrudu181@gmail.com | I7: Marripati | J7: Prathapa Rudrudu | K7: =_xludf.TEXTJOIN(" ",TRUE,I7:J7) -> #NAME? | L7: 1983 | M7: 1999 | N7: 1-INDIA IST | O7: +91 | P7: 9492961359 | Q7: =P7&"/"&L7&"/"&K7 -> #NAME? | R7: Tenali | S7: Ch Ramakrishna garu | T7: 8978416077 | U7: Koundinyasa, Sri vatsasa, Bharadwajasa | V7: N/A | W7: Yajur veda | X7: Telugu, Hindi, English | Y7: Telugu Hindi English | Z7: N/A | AA7: 3-ARCHAKA? | AB7: Not Applicable (Not Registering a Child under 13) | AC7: To improve swaram and sukthas | AD7: Low - Did not learn from Traditional Guru, but learnt from books/audio and perform daily Sandhya Vandanam and other poojas through books | AE7: Yes, This is High Priority for me | AF7: Yes | AG7: Yes | AH7: Yes | AI7: Yes
A8: 2025 | B8: 45913.378 | C8: 3-ARCHAKA? | D8: YES | E8: YES | F8: YES | G8: 1-ADULT OVER 16 YRS | H8: bkalyankumarhyd@gmail.com | I8: Kumar | J8: Kalyan | K8: =_xludf.TEXTJOIN(" ",TRUE,I8:J8) -> #NAME? | L8: 1994 | M8: 2012 | N8: 1-INDIA IST | O8: +91 | P8: 7386749513 | Q8: =P8&"/"&L8&"/"&K8 -> #NAME? | R8: Hyderabad | S8: Rama krishna rtd railway | T8: 98662 09719 | U8: N/A | V8: Kashyapasa, Srivatsasa | W8: Krishna Yajur | X8: Telugu, Hindhi, English | Y8: Telugu, Hindhi, English | Z8: N/A | AA8: 3-ARCHAKA? | AB8: Not Applicable (Not Registering a Child under 13) | AC8: To upgrade myself in Brahmanatva | AD8: Low - Did not learn from Traditional Guru, but learnt from books/audio and perform daily Sandhya Vandanam and other poojas through books | AE8: Yes, This is High Priority for me | AF8: Yes | AG8: Yes | AH8: Yes | AI8: Yes | AJ8: A high need for me to survive too
A9: 2025 | B9: 45913.995 | C9: 3-ARCHAKA? | D9: NO | E9: NO | F9: NO | G9: 1-ADULT OVER 16 YRS | H9: paturi.venkatanagasrinivas@gmail.com | I9: Paturi | J9: Srinivas Venkata Naga | K9: =_xludf.TEXTJOIN(" ",TRUE,I9:J9) -> #NAME? | L9: 1969 | M9: 1991 | N9: 1-INDIA IST | O9: +91 | P9: 9000577424 | Q9: =P9&"/"&L9&"/"&K9 -> #NAME? | R9: HYDERABAD | S9: KALPANA MANGALAMPALLI | T9: 8332914596 | U9: AYHREYASA, HARIDASA, KASYAPASA | V9: N/A | W9: Sukla Yajurveda | X9: Telugu | Y9: Telugu, English n Hindi | Z9: N/A | AA9: Private Emoloyee/Archaka | AB9: Not Applicable (Not Registering a Child under 13) | AC9: Due to financial burden. | AD9: High - Learnt from Traditional Guru in perfect swaram/uccharana - perform nithya Sandhya Vandanam and can recite few Suktams in su-swaram | AE9: Yes, This is High Priority for me | AF9: Yes | AG9: Yes | AH9: Yes | AI9: Yes | AJ9: NO ALTERNATE FOR ME TO LEAD FAMILY... DAUGHTER'S MARRIAGE n Son's higher education. My job is in dilemma as per management decision.
A10: 2025 | B10: 45943.424 | C10: 3-ARCHAKA? | D10: NO | E10: NO | F10: NO | G10: 1-ADULT OVER 16 YRS | H10: arkesharchakam2@gmail.com | I10: Archakam | J10: Arkeshwara Gurukkal | K10: =_xludf.TEXTJOIN(" ",TRUE,I10:J10) -> #NAME? | L10: 1981 | M10: 1997 | N10: 1-INDIA IST | O10: +91 | P10: 6281845580 | Q10: =P10&"/"&L10&"/"&K10 -> #NAME? | R10: Palamaner | S10: Aravinda Sai Kondamari | T10: +14806124302 | U10: Vasistasa, Bhargava, Kasyapasa | V10: N/A | W10: Yajur veda | X10: Telugu, Tamil, Kannada | Y10: Telugu, Kannada | Z10: N/A | AA10: 3-ARCHAKA? | AB10: Not Applicable (Not Registering a Child under 13) | AC10: Homam prakriya | AD10: High - Learnt from Traditional Guru in perfect swaram/uccharana - perform nithya Sandhya Vandanam and can recite few Suktams in su-swaram | AE10: Yes, This is High Priority for me | AF10: Yes | AG10: Yes | AH10: Yes | AI10: Yes | AJ10: I am working as an archaka at Temple. I can recite several suktas, but want to learn higher ceremonies like homam and yagnam.
A11: 2025 | B11: 45972.818 | C11: 3-ARCHAKA? | D11: NO | E11: NO | F11: NO | G11: 2-CHILD UNDER 16 YRS | H11: praveenbonala@gmail.com | I11: Bonala | J11: Arshith Sharma | K11: =_xludf.TEXTJOIN(" ",TRUE,I11:J11) -> #NAME? | L11: 2013 | M11: 2025 | N11: 5-OTHER | O11: +61 | P11: 434852893 | Q11: =P11&"/"&L11&"/"&K11 -> #NAME? | R11: Melbourne Australia | S11: Praveen Kumar Sharma bonala | T11: +61434852893 | U11: N/A | V11: Koundinyasa, Bharadwajasa | W11: Krishna Yajurveda | X11: English, Telugu | Y11: English, Telugu | Z11: Praveen Kumar Sharma Bonala, Gauthami Rajuri | AA11: 3-ARCHAKA? | AB11: Yes. Will Learn 1st Semester Syllabus along with Child | AC11: Praveen Kumar Sharma writing this comment- I feel truly blessed by the grace of God to have taken birth as Brahmin. During my childhood, I didnt get opportunity to learn ouir sacred tradition. My brother learnt something from Shringeri Shankar Matt- Warangal during college days. But I didnt get chance to learn from my brother due to my nature of study and job. Currently I am in Australia and have enough time for work life balance. I wanted to teach my kid about our country and our tradition. Currently he is learning from Youtube videos and books. I wanted him to learn swarayukta and from Guru upadesham. So he will continue our tradition and parampara and wont attract to other wester culture things. | AD11: Low - Did not learn from Traditional Guru, but learnt from books/audio and perform daily Sandhya Vandanam and other poojas through books | AE11: Yes, This is High Priority for me | AF11: Yes | AG11: Yes | AH11: Yes | AI11: Yes
A12: 2025 | B12: 45888.902 | C12: 4-REFERENCE? | D12: NO | E12: NO | F12: NO | G12: 1-ADULT OVER 16 YRS | H12: rudraramaj@gmail.com | I12: Rudra | J12: Rama | K12: =_xludf.TEXTJOIN(" ",TRUE,I12:J12) -> #NAME? | L12: 1987 | M12: 1996 | N12: 1-INDIA IST | O12: +91 | P12: 9392912521 | Q12: =P12&"/"&L12&"/"&K12 -> #NAME? | R12: Hyderabad | S12: Jana rudra Rama lingeswar sharma | T12: 9392912521 | U12: Bharadwajasa | V12: N/A | W12: Yajur veda | X12: Telugu | Y12: Telugu | Z12: N/A | AA12: Self employed | AB12: Not Applicable (Not Registering a Child under 13) | AC12: Intrested and important | AD12: High - Learnt from Traditional Guru in perfect swaram/uccharana - perform nithya Sandhya Vandanam and can recite few Suktams in su-swaram | AE12: Yes, This is High Priority for me | AF12: Yes | AG12: Yes | AH12: Yes | AI12: Yes
A13: 2025 | B13: 45915.457 | C13: 4-REFERENCE? | D13: NO | E13: NO | F13: NO | G13: 1-ADULT OVER 16 YRS | H13: kavi999@gmail.com | I13: Kavikondala | J13: Srinivas | K13: =_xludf.TEXTJOIN(" ",TRUE,I13:J13) -> #NAME? | L13: 1977 | M13: 1993 | N13: 1-INDIA IST | O13: +91 | P13: 9121200454 | Q13: =P13&"/"&L13&"/"&K13 -> #NAME? | R13: Hyderabad | S13: Diwakar | T13: +91 90000 19664 | U13: Bharadwajasa | V13: NA | W13: NA | X13: Telugu, Hindi, English | Y13: Telugu, Hindi, English | Z13: NA | AA13: Software engineer | AB13: Not Applicable (Not Registering a Child under 13) | AC13: Sandhya vandanam | AD13: None - Do not know much about this subject, but committed to learn | AE13: Yes, This is High Priority for me | AF13: Yes | AG13: Yes | AH13: Yes | AI13: Yes
A14: 2025 | B14: 45972.205 | C14: 4-REFERENCE? | D14: NO | E14: NO | F14: NO | G14: 1-ADULT OVER 16 YRS | H14: praffulshakhai@gmail.com | I14: Shakhai | J14: Prafful Sharma | K14: =_xludf.TEXTJOIN(" ",TRUE,I14:J14) -> #NAME? | L14: 1994 | M14: 2005 | N14: 1-INDIA IST | O14: +91 | P14: 7075211712 | Q14: =P14&"/"&L14&"/"&K14 -> #NAME? | R14: Hyderabad | S14: Online sent email | T14: Online | U14: NA | V14: Goutamasa,kashyapasa | W14: Yajur veda | X14: Telugu English hindi marati | Y14: Telugu English hindi | Z14: Na | AA14: Software engineer | AB14: Not Applicable (Not Registering a Child under 13) | AC14: Wanted to learn , follow and implement Veda dharma in daily life for better living | AD14: Low - Did not learn from Traditional Guru, but learnt from books/audio and perform daily Sandhya Vandanam and other poojas through books | AE14: Yes, This is High Priority for me | AF14: Yes | AG14: Yes | AH14: Yes | AI14: Yes
A15: 2025 | B15: 46001.895 | C15: 4-REFERENCE? | D15: NO | E15: NO | F15: NO | G15: 1-ADULT OVER 16 YRS | H15: veda729@gmail.com | I15: Simgavarjula | J15: Vedavyas | K15: =_xludf.TEXTJOIN(" ",TRUE,I15:J15) -> #NAME? | L15: 1996 | M15: 2025 | N15: 1-INDIA IST | O15: +91 | P15: 7893301281 | Q15: =P15&"/"&L15&"/"&K15 -> #NAME? | R15: Khammam | S15: Vedantam Rama Krishna Prasad | T15: 9441087938 | U15: N/A | V15: Srivatsasa, Vardeswasa | W15: Yajur Veda | X15: Telugu, English | Y15: Telugu, Hindi, English | Z15: N/A | AA15: Job Searching | AB15: Not Applicable (Not Registering a Child under 13) | AC15: Interested to learn and to be able to perform when required at home. | AD15: None - Do not know much about this subject, but committed to learn | AE15: Yes, This is High Priority for me | AF15: Yes | AG15: Yes | AH15: Yes | AI15: Yes | AJ15: I am excited to join and learn. Thank you for giving this opportunity of sharing my details with you.
A16: 2025 | B16: 46013.485 | C16: 4-REFERENCE? | D16: NO | E16: NO | F16: NO | G16: 1-ADULT OVER 16 YRS | H16: durgaprasadvaranasi08@gmail.com | I16: Varanasi | J16: Durgaprasad | K16: =_xludf.TEXTJOIN(" ",TRUE,I16:J16) -> #NAME? | L16: 1982 | M16: 2010 | N16: 3-USA CST | O16: +1 | P16: 2039092885 | Q16: =P16&"/"&L16&"/"&K16 -> #NAME? | R16: Aubrey | S16: NA | T16: NA | U16: Koundinyasa, | V16: NA | W16: Yajur | X16: Telugu, Hindi, English | Y16: Telugu , Hindi , English | Z16: NA | AA16: Software engineer | AB16: Not Applicable (Not Registering a Child under 13) | AC16: Ganapathi homam, Rudra homam…etc | AD16: Low - Did not learn from Traditional Guru, but learnt from books/audio and perform daily Sandhya Vandanam and other poojas through books | AE16: Yes, This is High Priority for me | AF16: Yes | AG16: Yes | AH16: Yes | AI16: Yes | AJ16: Main goal is -I have to perform my Poojas at home without anyone’s help ( can be any Pooja or homam). And to retain our culture and spread it to next generations
A17: 2025 | B17: 46014.899 | C17: 4-REFERENCE? | D17: NO | E17: NO | F17: NO | G17: 1-ADULT OVER 16 YRS | H17: nagarajugudipudi@gmail.com | I17: Gudipudi | J17: Nagaraju | K17: =_xludf.TEXTJOIN(" ",TRUE,I17:J17) -> #NAME? | L17: 1963 | M17: 1992 | N17: 1-INDIA IST | O17: +91 | P17: 9866229986 | Q17: =P17&"/"&L17&"/"&K17 -> #NAME? | R17: HYDERABAD | S17: GUDIPUDI PRASUNA | T17: 9491453386 | U17: SHANDILYASA, MAITRAVARANA, KOUNDINYASA | V17: NA | W17: Yajurveda | X17: Telugu, Hindi, English | Y17: Telugu, Hindi, English. | Z17: NA | AA17: SBI Bank Manager Retired | AB17: Not Applicable (Not Registering a Child under 13) | AC17: Nithya Karma, Pancha Suktas, Visesha Suktas, Rudra Pada Patham, Smartha Poojas, Mahanyaasam, Smartham, Upanishads, Maha Narayanam, Arunam, Veda Aseervachanam, Ghana Swasthi., | AD17: Low - Did not learn from Traditional Guru, but learnt from books/audio and perform daily Sandhya Vandanam and other poojas through books | AE17: Not sure due to other commitments | AF17: Yes | AG17: Yes | AH17: Yes | AI17: Yes | AJ17: Atleast now I should be able to byheart the necessary slokas and sutras to do nitya pooja.
A18: 2025 | B18: 46015.121 | C18: 4-REFERENCE? | D18: NO | E18: NO | F18: NO | G18: 1-ADULT OVER 16 YRS | H18: prasadevs@gmail.com | I18: Emani | J18: V S Prasad | K18: =_xludf.TEXTJOIN(" ",TRUE,I18:J18) -> #NAME? | L18: 1961 | M18: 1981 | N18: 1-INDIA IST | O18: +91 | P18: 7095490205 | Q18: =P18&"/"&L18&"/"&K18 -> #NAME? | R18: hyderabad | S18: what app | T18: what app | U18: gowthamasa haritasa Gagresa | V18: not applicable | W18: rig veda | X18: telugu englush | Y18: telugu english | Z18: not applicable | AA18: rtd | AB18: Not Applicable (Not Registering a Child under 13) | AC18: nitya vidhi | AD18: Low - Did not learn from Traditional Guru, but learnt from books/audio and perform daily Sandhya Vandanam and other poojas through books | AE18: Not sure due to other commitments | AF18: Yes | AG18: Yes | AH18: Yes | AI18: Yes
A19: 2025 | B19: 46016.441 | C19: 4-REFERENCE? | D19: NO | E19: NO | F19: NO | G19: 1-ADULT OVER 16 YRS | H19: venkata.yammanuru@gmail.com | I19: Yammanuru | J19: Venkata Phaneendra | K19: =_xludf.TEXTJOIN(" ",TRUE,I19:J19) -> #NAME? | L19: 1992 | M19: 2007 | N19: 1-INDIA IST | O19: +91 | P19: 9154320012 | Q19: =P19&"/"&L19&"/"&K19 -> #NAME? | R19: Kadiri | S19: G Vishnu Sri vardhan | T19: 9491380172 | U19: N/A | V19: Sri vasthasa, Aathreyasa | W19: Yajur veda | X19: Telugu, English, Hindi | Y19: Telugu, English, Hindi | Z19: N/A | AA19: Software engineer | AB19: Not Applicable (Not Registering a Child under 13) | AC19: Self Intrest. | AD19: None - Do not know much about this subject, but committed to learn | AE19: Yes, This is High Priority for me | AF19: Yes | AG19: Yes | AH19: Yes | AI19: Yes | AJ19: To perform daily pooja.
A20: 2025 | B20: 46021.302 | C20: 4-REFERENCE? | D20: NO | E20: NO | F20: NO | G20: 1-ADULT OVER 16 YRS | H20: bharatchandraji@gmail.com | I20: Mukkavalli | J20: Bharat Chandra | K20: =_xludf.TEXTJOIN(" ",TRUE,I20:J20) -> #NAME? | L20: 2002 | M20: 2012 | N20: 1-INDIA IST | O20: +91 | P20: 9121277268 | Q20: =P20&"/"&L20&"/"&K20 -> #NAME? | R20: Mumbai | S20: Viswa Prasad Mukkavalli | T20: 9849406522 | U20: N/A | V20: Kousikasa, Athreyasa | W20: Yajur Veda | X20: Telugu, Hindi, English | Y20: Telugu-Beginner, English-Full Proficiency, Hindi-Proficient | Z20: N/A | AA20: M.Tech Student | AB20: 5- STUDENT OVER 13. Not Applicable | AC20: I have always wanted to learn the vedas. | AD20: Low - Did not learn from Traditional Guru, but learnt from books/audio and perform daily Sandhya Vandanam and other poojas through books | AE20: Yes, This is Top Priority for me | AF20: Yes | AG20: Yes | AH20: Yes | AI20: Yes
A21: 2025 | B21: 46021.849 | C21: 4-REFERENCE? | D21: NO | E21: NO | F21: NO | G21: 1-ADULT OVER 16 YRS | H21: nelapatlasastry@gmail.com | I21: Nelapatla | J21: Subbarama Sastry | K21: =_xludf.TEXTJOIN(" ",TRUE,I21:J21) -> #NAME? | L21: 1994 | M21: 2008 | N21: 1-INDIA IST | O21: +91 | P21: 7675030340 | Q21: =P21&"/"&L21&"/"&K21 -> #NAME? | R21: Hyderabad | S21: Nelabhotla yeswanth kumar | T21: 9381583342 | U21: Bharadhwaja, koundinyasa, kasyapasa | V21: N/A | W21: Krishna Yajurveda | X21: Telugu, English and hindi | Y21: Telugu and english | Z21: N/A | AA21: Public sector employee | AB21: 5- STUDENT OVER 13. Not Applicable | AC21: For peace and teach my kids in future | AD21: None - Do not know much about this subject, but committed to learn | AE21: Yes, This is Top Priority for me | AF21: Yes | AG21: Yes | AH21: Yes | AI21: Yes
A22: 2025 | B22: 46023.034 | C22: 4-REFERENCE? | D22: NO | E22: NO | F22: NO | G22: 1-ADULT OVER 16 YRS | H22: barurao@rediffmail.com | I22: Baru | J22: Narasimha Rao | K22: =_xludf.TEXTJOIN(" ",TRUE,I22:J22) -> #NAME? | L22: 1963 | M22: 1992 | N22: 1-INDIA IST | O22: +91 | P22: 8484970065 | Q22: =P22&"/"&L22&"/"&K22 -> #NAME? | R22: Pune | S22: Raghavendra Rao | T22: 9247465125 | U22: Bharadwaja/ vashishta / kasyapasa | V22: N/A | W22: Rig veda | X22: Telugu | Y22: English; hindi | Z22: N/A | AA22: Retired | AB22: 5- STUDENT OVER 13. Not Applicable | AC22: Veda chanting | AD22: Low - Did not learn from Traditional Guru, but learnt from books/audio and perform daily Sandhya Vandanam and other poojas through books | AE22: Yes, This is Top Priority for me | AF22: Yes | AG22: Yes | AH22: Yes | AI22: Yes
A23: 2026 | B23: 46154.016 | C23: 4-REFERENCE? | D23: TBD | E23: TBD | F23: TBD | G23: 1-ADULT OVER 16 YRS | H23: vasishtaswarna@gmail.com | I23: Swarna | J23: Srikrishna Vasishta | K23: =_xludf.TEXTJOIN(" ",TRUE,I23:J23) -> #NAME? | L23: 2008 | M23: 2019 | N23: 1-INDIA IST | O23: +91 | P23: 7013164026 | Q23: =P23&"/"&L23&"/"&K23 -> #NAME? | R23: Hyderabad | S23: Nadendla Sudheer Kumar | T23: 8885578787 | U23: N/A | V23: Koundinyasa, Kasyapasa | W23: Yajurvedam | X23: Telugu, English, Hindi | Y23: Telugu, English, Hindi | Z23: Swarna Siva Subrahmanyam, Swarna Harichandana | AA23: Student | AB23: 5- STUDENT OVER 13. Not Applicable | AC23: Smartam | AD23: None - Do not know much about this subject, but committed to learn | AE23: Not sure due to other commitments | AF23: Yes | AG23: Yes | AH23: Yes | AI23: Yes
A24: 2024 | B24: 45386.869 | C24: 5-WHATSAPP? | D24: YES | E24: NO | F24: NO | G24: 2-CHILD UNDER 16 YRS | H24: mvbhavani86@gmail.com | I24: Neelalohith | J24: Hanumath | K24: =_xludf.TEXTJOIN(" ",TRUE,I24:J24) -> #NAME? | L24: 2014 | N24: 2-USA EST | O24: +1 | P24: 9492728342 | Q24: =P24&"/"&L24&"/"&K24 -> #NAME? | R24: North carolina | S24: Kotam Raju srinivas rao | T24: Kotam Raju srinivas rao | U24: Koundinyasa, Kasyapasa, Brahmachari | V24: Koundinyasa, Kasyapasa, Brahmachari | W24: Yajur veda | X24: Telugu | Y24: English | Z24: M.chandra Kaladhar | AA24: N/A | AB24: Yes. Will Learn 1st Year Syllabus along with Child | AC24: To learn nityakarma puja | AD24: None - Do not know much about this subject, but committed to learn | AE24: Yes, This is High Priority for me | AF24: Yes | AG24: Yes | AH24: Yes | AI24: Yes
A25: 2024 | B25: 45273.483 | C25: YES | D25: YES | E25: YES | F25: YES | G25: 1-ADULT OVER 16 YRS | H25: tlbhaskar@gmail.com | I25: Lakshman | J25: Bhaskar | K25: =_xludf.TEXTJOIN(" ",TRUE,I25:J25) -> #NAME? | L25: 1960 | N25: 2-USA EST | O25: +1 | P25: 2487676387 | Q25: =P25&"/"&L25&"/"&K25 -> #NAME? | R25: Detroit | S25: Srinath Kunduruthy | T25: Srinath Kunduruthy | U25: Srivatsa, Haridasa, Kashyapa | V25: Srivatsa, Haridasa, Kashyapa | W25: Yajur | X25: Tamil, Telugu, English | Y25: Tamil, English | Z25: NA | AA25: IT professional | AB25: Not Applicable (Not Registering a Child under 13) | AC25: I want improve my chanting of vedas as I already learnt Guru Mula Rudram, Chamakam. Suktas basic ones | AD25: High - Learnt from Traditional Guru in perfect swaram/uccharana - perform nithya Sandhya Vandanam and can recite few Suktams in su-swaram | AE25: Yes, This is High Priority for me | AF25: Yes | AG25: Yes | AH25: Yes | AI25: Yes | AJ25: I want to learn Mahanyasam which is being taught in AP which is very elaborate to start with
A26: 2024 | B26: 45278.249 | C26: YES | D26: YES | E26: YES | F26: YES | G26: 1-ADULT OVER 16 YRS | H26: bvmk_rao27@rediffmail.com | I26: Bhattiprolu | J26: Venkata Murali Krishna Rao | K26: =_xludf.TEXTJOIN(" ",TRUE,I26:J26) -> #NAME? | L26: 1976 | N26: 1-INDIA IST | O26: +91 | P26: 9440378057 | Q26: =P26&"/"&L26&"/"&K26 -> #NAME? | R26: Hyderabad | S26: Satish sarma tumuluri guruvugaru (Budwel veda patasala) | T26: Satish sarma tumuluri guruvugaru (Budwel veda patasala) | U26: Koundinyasa, Bharadwajasa, Bharadwajasa | V26: Koundinyasa, Bharadwajasa, Bharadwajasa | W26: Yajur veda | X26: Telugu, English ,Hindi | Y26: Telugu ,English, Hindi | Z26: N/A | AA26: Private Sector. | AB26: Not Applicable (Not Registering a Child under 13) | AC26: I want to be able to do nitya karma that brahmin should be doing. Want to lead life as per Sanatana dharma. | AD26: Low - Did not learn from Traditional Guru, but learnt from books/audio and perform daily Sandhya Vandanam and other poojas through books | AE26: Yes, This is High Priority for me | AF26: Yes | AG26: Yes | AH26: Yes | AI26: Yes | AJ26: I am Sandhyavandanam 3 times a day but want sookthams and other nitya karma's like pitru tarpanas and daily Puja with proper shodasa vidhanam. Budwel vedapatasala guruvu garu suggested your classes.
A27: 2024 | B27: 45294.75 | C27: YES | D27: YES | E27: YES | F27: YES | G27: 1-ADULT OVER 16 YRS | H27: ssripada@gmail.com | I27: Shripada | J27: Subrahmanya Srinivasa | K27: =_xludf.TEXTJOIN(" ",TRUE,I27:J27) -> #NAME? | L27: 1963 | N27: 2-USA EST | O27: +1 | P27: 6474041774 | Q27: =P27&"/"&L27&"/"&K27 -> #NAME? | R27: Toronto, Canada | S27: SRINIVAS MARLA | T27: SRINIVAS MARLA | U27: Kaushikasa, Kaundinyasa, Gauthamasa | V27: Kaushikasa, Kaundinyasa, Gauthamasa | W27: Yajur Veda | X27: Telugu, English, Hindi, Kannada | Y27: Telugu, English | Z27: N/A | AA27: Civil Enginner | AB27: Not Applicable (Not Registering a Child under 13) | AC27: To better understand and knowing of Vedas and to gain spiritual knowledge | AD27: Low - Did not learn from Traditional Guru, but learnt from books/audio and perform daily Sandhya Vandanam and other poojas through books | AE27: Yes, This is High Priority for me | AF27: Yes | AG27: Yes | AH27: Yes | AI27: Yes | AJ27: I would like to join the course and develop my skills. Thanks
A28: 2024 | B28: 45298.909 | C28: YES | D28: YES | E28: YES | F28: YES | G28: 1-ADULT OVER 16 YRS | H28: vedula.abhishek1@gmail.com | I28: Vedula | J28: Abhishek | K28: =_xludf.TEXTJOIN(" ",TRUE,I28:J28) -> #NAME? | L28: 1995 | N28: 1-INDIA IST | O28: +91 | P28: 7207128428 | Q28: =P28&"/"&L28&"/"&K28 -> #NAME? | R28: Hyderabad | S28: VEDULA ABHISHEK | T28: VEDULA ABHISHEK | U28: Bharadwaja, Srivatsa, Kaundinyasa | V28: Bharadwaja, Srivatsa, Kaundinyasa | W28: SAMA VEDA | X28: Telugu, English | Y28: Telugu, English | Z28: N/A | AA28: Software Engineer | AB28: Not Applicable (Not Registering a Child under 13) | AC28: I couldn't learn this during my childhood. I have interest in learning nithyakarma, smartham , pooja vidhis so that I can stick to my cultural roots. | AD28: None - Do not know much about this subject, but committed to learn | AE28: Yes, This is High Priority for me | AF28: Yes | AG28: Yes | AH28: Yes | AI28: Yes | AJ28: Although many of my family members are into paurohitham unfortunately I couldn't learn from them during my childhood. I will be privileged if I get into the course and find a guru. 🙏
A29: 2024 | B29: 45298.993 | C29: YES | D29: YES | E29: YES | F29: YES | G29: 2-CHILD UNDER 16 YRS | H29: raviec04@gmail.com | I29: Tadepally | J29: Sri Rama Karthikeya Sharma | K29: =_xludf.TEXTJOIN(" ",TRUE,I29:J29) -> #NAME? | L29: 2013 | N29: 1-INDIA IST | O29: +91 | P29: 9940343476 | Q29: =P29&"/"&L29&"/"&K29 -> #NAME? | R29: Hyderabad | S29: Sai Srinivas Jagarlamudi | T29: Sai Srinivas Jagarlamudi | U29: Harithasa, Gauthamasa, N/A | V29: Harithasa, Gauthamasa, N/A | W29: Yajur | X29: Telugu | Y29: Telugu, Hindi, English | Z29: Ravikanth Sharma Tadepally | AA29: 5th Grade | AB29: Yes. Will Learn 1st Year Syllabus along with Child | AC29: To follow sanatana dharmam as prescribed in Vedas | AD29: Low - Did not learn from Traditional Guru, but learnt from books/audio and perform daily Sandhya Vandanam and other poojas through books | AE29: Yes, This is High Priority for me | AF29: Yes | AG29: Yes | AH29: Yes | AI29: Yes
A30: 2024 | B30: 45323.017 | C30: YES | D30: YES | E30: YES | F30: YES | G30: 1-ADULT OVER 16 YRS | H30: sudan1955@gmail.com | I30: Kurada | J30: Madhusudana Rao | K30: =_xludf.TEXTJOIN(" ",TRUE,I30:J30) -> #NAME? | L30: 1955 | N30: 1-INDIA IST | O30: +91 | P30: 8500945799 | Q30: =P30&"/"&L30&"/"&K30 -> #NAME? | R30: Hyderabad | S30: Venkata Satya Vijay Kommaraju | T30: Venkata Satya Vijay Kommaraju | U30: Srivatsasa, Sandilyasa, Sandilyasa | V30: Srivatsasa, Sandilyasa, Sandilyasa | W30: Yajur Veda Krishna Sakha | X30: Telugu | Y30: Telugu, English, Hindi | Z30: N/A | AA30: General Manager BSNL Retired | AB30: Not Applicable (Not Registering a Child under 13) | AC30: Interested in our tradition. Know Sandhyavandanam etc and some sukthas | AD30: Low - Did not learn from Traditional Guru, but learnt from books/audio and perform daily Sandhya Vandanam and other poojas through books | AE30: Yes, This is High Priority for me | AF30: Yes | AG30: Yes | AH30: Yes | AI30: Yes | AJ30: Once occasional smoker. Stopped long back
A31: 2024 | B31: 45323.074 | C31: YES | D31: YES | E31: YES | F31: YES | G31: 1-ADULT OVER 16 YRS | H31: charans92@gmail.com | I31: Indrakanti | J31: Shiva Charan | K31: =_xludf.TEXTJOIN(" ",TRUE,I31:J31) -> #NAME? | L31: 1992 | N31: 4-USA MST/PST | O31: +1 | P31: 8509806681 | Q31: =P31&"/"&L31&"/"&K31 -> #NAME? | R31: Seattle | S31: Rama Krishna | T31: Rama Krishna | U31: Srivatsasa, Bharadwajasa, N/A | V31: Srivatsasa, Bharadwajasa, N/A | W31: Yajur Veda | X31: Telugu English Hindi | Y31: Telugu English Hindi | Z31: N/A | AA31: Hardware Engineer | AB31: Not Applicable (Not Registering a Child under 13) | AC31: Out of Passion | AD31: Low - Did not learn from Traditional Guru, but learnt from books/audio and perform daily Sandhya Vandanam and other poojas through books | AE31: Yes, This is High Priority for me | AF31: Yes | AG31: Yes | AH31: Yes | AI31: Yes | AJ31: Phone Number is +18509806681
A32: 2024 | B32: 45323.179 | C32: YES | D32: YES | E32: YES | F32: YES | G32: 1-ADULT OVER 16 YRS | H32: narasimharaokvn@rediffmail.com | I32: Kommaraju | J32: Venkata Narasimha Rao | K32: =_xludf.TEXTJOIN(" ",TRUE,I32:J32) -> #NAME? | L32: 1956 | N32: 1-INDIA IST | O32: +91 | P32: 9949093634 | Q32: =P32&"/"&L32&"/"&K32 -> #NAME? | R32: HYDERABAD | S32: Kommaraju venkata sarya vijay | T32: Kommaraju venkata sarya vijay | U32: Koundinyasa, Bharadwaja, Bharadwaja | V32: Koundinyasa, Bharadwaja, Bharadwaja | W32: Krishna Yajur Veda | X32: Telugu/hindi/english | Y32: Telugu/hindi/english | Z32: N/A | AA32: Bank AGM RETD. | AB32: Not Applicable (Not Registering a Child under 13) | AC32: Vedas meanings and nitya karmalu vidhanam | AD32: None - Do not know much about this subject, but committed to learn | AE32: Yes, This is High Priority for me | AF32: Yes | AG32: Yes | AH32: Yes | AI32: Yes | AJ32: Please allow me to participate
A33: 2024 | B33: 45329.44 | C33: YES | D33: YES | E33: YES | F33: YES | G33: 1-ADULT OVER 16 YRS | H33: praveendaita@gmail.com | I33: Daita | J33: Praveen | K33: =_xludf.TEXTJOIN(" ",TRUE,I33:J33) -> #NAME? | L33: 1979 | N33: 1-INDIA IST | O33: +91 | P33: 9885981818 | Q33: =P33&"/"&L33&"/"&K33 -> #NAME? | R33: Hyderabad | S33: M Ravi Kiran Sharma | T33: M Ravi Kiran Sharma | U33: Srivathsa, Bharadwajas, Haritasa | V33: Srivathsa, Bharadwajas, Haritasa | W33: Krishna yajur veda | X33: Telugu, English, Hindi | Y33: Telugu, English, Hindi | Z33: N/A | AA33: Operations Manager | AB33: Not Applicable (Not Registering a Child under 13) | AC33: To practice my daily rituals | AD33: Low - Did not learn from Traditional Guru, but learnt from books/audio and perform daily Sandhya Vandanam and other poojas through books | AE33: Yes, This is High Priority for me | AF33: Yes | AG33: Yes | AH33: Yes | AI33: Yes
A34: 2024 | B34: 45337.445 | C34: YES | D34: YES | E34: YES | F34: YES | G34: 1-ADULT OVER 16 YRS | H34: srivatsakurada@gmail.com | I34: Kurada | J34: Srivatsa | K34: =_xludf.TEXTJOIN(" ",TRUE,I34:J34) -> #NAME? | L34: 1997 | N34: 4-USA MST/PST | O34: +1 | P34: 2067781986 | Q34: =P34&"/"&L34&"/"&K34 -> #NAME? | R34: Redmond | S34: Vijay Kommaraju | T34: Vijay Kommaraju | U34: Srivatsasa, Sandilyasa, N/A | V34: Srivatsasa, Sandilyasa, N/A | W34: Krishna Yajur Veda | X34: Telugu, Hindi, English | Y34: English, Hindi, Telugu | Z34: N/A | AA34: Software Engineer | AB34: Not Applicable (Not Registering a Child under 13) | AC34: I want to learn ancient culture | AD34: None - Do not know much about this subject, but committed to learn | AE34: Not sure due to other commitments | AF34: Yes | AG34: Yes | AH34: Yes | AI34: Yes
A35: 2024 | B35: 45341.015 | C35: YES | D35: YES | E35: YES | F35: YES | G35: 1-ADULT OVER 16 YRS | H35: srkvsagar@gmail.com | I35: Sathuvalli | J35: Vidyasagar | K35: =_xludf.TEXTJOIN(" ",TRUE,I35:J35) -> #NAME? | L35: 1980 | N35: 4-USA MST/PST | O35: +1 | P35: 5412231699 | Q35: =P35&"/"&L35&"/"&K35 -> #NAME? | R35: Kennewick | S35: Bharat Vyakaranam | T35: Bharat Vyakaranam | U35: Bharadwaja, Koundinasya, Vishwamitra | V35: Bharadwaja, Koundinasya, Vishwamitra | W35: Yajur Veda | X35: Telugu, Kannada, English, Tamil, Hindi | Y35: Telugu, Kannada, English | Z35: N/A | AA35: Associate Professor | AB35: Not Applicable (Not Registering a Child under 13) | AC35: Complete Veda | AD35: None - Do not know much about this subject, but committed to learn | AE35: Yes, This is High Priority for me | AF35: Yes | AG35: Yes | AH35: Yes | AI35: Yes
A36: 2024 | B36: 45350.935 | C36: YES | D36: YES | E36: YES | F36: YES | G36: 1-ADULT OVER 16 YRS | H36: nirapavankumar@gmail.com | I36: Niraghatam | J36: Pavan | K36: =_xludf.TEXTJOIN(" ",TRUE,I36:J36) -> #NAME? | L36: 1981 | N36: 3-USA CST | O36: +1 | P36: 5123178882 | Q36: =P36&"/"&L36&"/"&K36 -> #NAME? | R36: Austin | S36: Pravallika Kautha | T36: Pravallika Kautha | U36: Bhargavasa, Kaundinyasa, N/A | V36: Bhargavasa, Kaundinyasa, N/A | W36: Yajur Veda | X36: Telugu, English | Y36: Telugu, English | Z36: Niraghatam Subbarao, Niraghatam Parvathi Prasanna | AA36: IT | AB36: Not Applicable (Not Registering a Child under 13) | AC36: To learn Vedam and correct pronunciation | AD36: Low - Did not learn from Traditional Guru, but learnt from books/audio and perform daily Sandhya Vandanam and other poojas through books | AE36: Yes, This is High Priority for me | AF36: Yes | AG36: Yes | AH36: Yes | AI36: Yes
A37: 2024 | B37: 45372.905 | C37: YES | D37: YES | E37: YES | F37: YES | G37: 1-ADULT OVER 16 YRS | H37: parthumanikonda04@gmail.com | I37: Manikonda | J37: Parthasaradhi | K37: =_xludf.TEXTJOIN(" ",TRUE,I37:J37) -> #NAME? | L37: 2004 | N37: 1-INDIA IST | O37: +91 | P37: 7995955739 | Q37: =P37&"/"&L37&"/"&K37 -> #NAME? | R37: Hyderabad | S37: Yathin Chandra Manikonda | T37: Yathin Chandra Manikonda | U37: Kowndinyasa, Harithasa, N/A | V37: Kowndinyasa, Harithasa, N/A | W37: Krishna Yajur vedam | X37: Telugu, English | Y37: Telugu , English | Z37: N/A | AA37: Btech 3rd year student | AB37: Not Applicable (Not Registering a Child under 13) | AC37: To practice our Vedic dharma | AD37: Low - Did not learn from Traditional Guru, but learnt from books/audio and perform daily Sandhya Vandanam and other poojas through books | AE37: Yes, This is High Priority for me | AF37: Yes | AG37: Yes | AH37: Yes | AI37: Yes | AJ37: NA
A38: 2024 | B38: 45372.915 | C38: YES | D38: YES | E38: YES | F38: YES | G38: 1-ADULT OVER 16 YRS | H38: siva.tatavarthi@yahoo.co.in | I38: Tatavarthi | J38: Sivaramakrishna | K38: =_xludf.TEXTJOIN(" ",TRUE,I38:J38) -> #NAME? | L38: 1973 | N38: 1-INDIA IST | O38: +91 | P38: 9962557438 | Q38: =P38&"/"&L38&"/"&K38 -> #NAME? | R38: Hyderabad | S38: Manikonda yatin chandra | T38: Manikonda yatin chandra | U38: Koundinyasa, Bharadwajasa, Kousikasa | V38: Koundinyasa, Bharadwajasa, Kousikasa | W38: Yajur veda | X38: Telugu | Y38: Telugu | Z38: NA | AA38: Architect | AB38: Not Applicable (Not Registering a Child under 13) | AC38: As per syllabus | AD38: High - Learnt from Traditional Guru in perfect swaram/uccharana - perform nithya Sandhya Vandanam and can recite few Suktams in su-swaram | AE38: Yes, This is High Priority for me | AF38: Yes | AG38: Yes | AH38: Yes | AI38: Yes | AJ38: Very keen
A39: 2024 | B39: 45372.939 | C39: YES | D39: YES | E39: YES | F39: YES | G39: 1-ADULT OVER 16 YRS | H39: sreekararockzz@gmail.com | I39: Mokshagundam | J39: Sreekara | K39: =_xludf.TEXTJOIN(" ",TRUE,I39:J39) -> #NAME? | L39: 1995 | N39: 1-INDIA IST | O39: +91 | P39: 9035023670 | Q39: =P39&"/"&L39&"/"&K39 -> #NAME? | R39: Bangalore | S39: N/A | T39: N/A | U39: Bharadwajasa, kowndinyasa, N/A | V39: Bharadwajasa, kowndinyasa, N/A | W39: Yajur veda | X39: English, Telugu | Y39: English, Telugu | Z39: N/A | AA39: Software engineer | AB39: Not Applicable (Not Registering a Child under 13) | AC39: To be able to perform my nitya karma and daily Pooja | AD39: Low - Did not learn from Traditional Guru, but learnt from books/audio and perform daily Sandhya Vandanam and other poojas through books | AE39: Yes, This is High Priority for me | AF39: Yes | AG39: Yes | AH39: Yes | AI39: Yes
